<?xml version="1.0"?>
<robot name="vp6242">
	<!--
		J1   J2   J3   J4   J5   J6
		160  120  160  160  120  360
	   -160 -120   19 -160 -120 -360
	-->
  <link name="base_link">
    <visual>
	  <geometry>
	    <cylinder length="0.125" radius="0.08"/>
	  </geometry>
	  <origin xyz="0 0 0.0775"/>
	  <material name="base_link">
        <color rgba="0.3 0.3 0.3 1"/>
      </material>
    </visual>
  </link>
	
  <link name="link0">
    <visual>
      <geometry>
        <cylinder length="0.125" radius="0.03"/>
      </geometry>
      <origin xyz="0 0 0.0625"/>
      <material name="link">
        <color rgba="0.8 0.8 0.8 1"/>
      </material>
    </visual>
  </link>

  <joint name="J1" type="revolute">
    <axis xyz="0 0 1"/>
    <limit effort="1000.0" lower="-2.792526" upper="2.792526" velocity="1.0"/>
    <origin rpy="0 0 0" xyz="0.0 0.0 0.155"/>
    <parent link="base_link"/>
    <child link="link0"/>
  </joint>

  <link name="link1">
    <visual>
      <geometry>
        <cylinder length="0.210" radius="0.03"/>
      </geometry>
      <origin xyz="0 0 0.105"/>
      <material name="link"/>
    </visual>
  </link>

  <joint name="J2" type="revolute">
    <axis xyz="0 1 0"/>
    <limit effort="1000.0" lower="-2.094394" upper="2.094394" velocity="1.0"/>
    <origin rpy="0 0 0" xyz="0.0 0.0 0.125"/>
    <parent link="link0"/>
    <child link="link1"/>
  </joint>
  
  <link name="link2">
    <visual>
      <geometry>
        <cylinder length="0.075" radius="0.03"/>
      </geometry>
	  <origin rpy="0 0 0" xyz="0 0 0.0375"/>
	  <material name="joint">
      <color rgba="0.5 0.5 0.5 1"/>
      </material>
    </visual>
  </link>
 	
 <joint name="J3" type="revolute">
    <axis xyz="0 1 0"/>
    <limit effort="1000.0" lower="-1.239183" upper="1.221730" velocity="1.0"/>
    <origin rpy="0 0 0" xyz="0.0 0.0 0.210"/>
    <parent link="link1"/>
    <child link="link2"/>
  </joint>


  <link name="link3">
    <visual>
    <geometry>
      <cylinder length="0.311" radius="0.03"/>
    </geometry>
		<origin rpy="0 1.570796 0" xyz="0.0545 0.0 0.0"/>
		<material name="link"/>
    </visual>
  </link>
  
  <joint name="J4" type="revolute">
    <axis xyz="1 0 0"/>
    <limit effort="1000.0" lower="-2.792526" upper="2.792526" velocity="1.0"/>
    <origin rpy="0 0 0" xyz="0.0 0.0 0.075"/>
    <parent link="link2"/>
    <child link="link3"/>
  </joint>

  <link name="link4">
    <visual>
      <geometry>
      <cylinder length="0.060" radius="0.0325"/>
      </geometry>
	  <origin rpy="0 1.570796 0" xyz="0.030 0.0 0.0"/>
	  <material name="joint"/>
    </visual>
  </link>
 	
  <joint name="J5" type="revolute">
    <axis xyz="0 1 0"/>
    <limit effort="1000.0" lower="-2.094394" upper="2.094394" velocity="1.0"/>
    <origin rpy="0 0 0" xyz="0.210 0.0 0.0"/>
    <parent link="link3"/>
    <child link="link4"/>
  </joint>

   <link name="link5">
    <visual>
      <geometry>
      <cylinder length="0.010" radius="0.0325"/>
      </geometry>
	  <origin rpy="0 1.570796 0" xyz="0.005 0.0 0.0"/>
	  <material name="link"/>
    </visual>
  </link>
 	
  <joint name="J6" type="revolute">
    <axis xyz="1 0 0"/>
    <limit effort="1000.0" lower="-2.094394" upper="2.094394" velocity="1.0"/>
    <origin rpy="0 0 0" xyz="0.06 0.0 0.0"/>
    <parent link="link4"/>
    <child link="link5"/>
  </joint>
<!--
	<link name="link6">
    <visual>
      <geometry>
			  <box size="0.050 0.030 0.010"/>
			</geometry>
			<origin xyz="0 0 0.005"/>
			<material name="joint"/>
    </visual>
  </link>
	
	<joint name="J7" type="revolute">
		<axis xyz="0 0 1"/>
    <limit effort="1000.0" lower="-1.30899" upper="0.43633" velocity="1.0"/> 
    <origin rpy="0 0 0" xyz="0.0 0.0 0.068"/>
    <parent link="link5"/>
    <child link="link6"/>
  </joint>
-->
<!--	
  <link name="gripper_left">
    <visual>
      <geometry>
			  <box size="0.020 0.002 0.030"/>
			</geometry>
			<origin xyz="0 0 0.025"/>
			<material name="gripper">
				<color rgba="0.8 0.8 0.3 1"/>
			</material>
    </visual>
  </link>

	<joint name="J7_left" type="prismatic">
    <axis xyz="0 1 0"/>
    <limit effort="1000.0" lower="0.013" upper="0.0215" velocity="1.0"/>
    <origin rpy="0 0 0" xyz="0.0 0.0 0.0"/>
    <parent link="link6"/>
    <child link="gripper_left"/>
  </joint>
  
  <link name="gripper_right">
    <visual>
      <geometry>
			  <box size="0.020 0.002 0.030"/>
			</geometry>
			<origin xyz="0 0 0.025"/>
			<material name="gripper"/>
    </visual>
  </link>

	<joint name="J7_right" type="prismatic">
    <axis xyz="0 1 0"/>
    <limit effort="1000.0" lower="-0.013" upper="-0.0215" velocity="1.0"/>
    <origin rpy="0 0 0" xyz="0.0 0.0 0.0"/>
    <parent link="link6"/>
    <child link="gripper_right"/>
  </joint>
-->
</robot>
