<?xml version="1.0" ?>
<!-- =================================================================================== -->
<!-- |    This document was autogenerated by xacro from urdf/vp6242.xacro              | -->
<!-- |    EDITING THIS FILE BY HAND IS NOT RECOMMENDED                                 | -->
<!-- =================================================================================== -->
<robot name="vp6242" xmlns:xacro="http://www.ros.org/wiki/xacro">
  <link name="base_link}">
    <visual>
      <geometry>
        <mesh filename="package://denso_common/meshes/vp6242/visual/base.dae" scale="0.001 0.001 0.001"/>
      </geometry>
      <origin rpy="-1.570796 3.141592 0" xyz="0 0 0"/>
    </visual>
    <collision>
      <geometry>
        <mesh filename="package://denso_common/meshes/vp6242/collision/base.dae" scale="0.001 0.001 0.001"/>
      </geometry>
      <origin rpy="-1.570796 3.141592 0" xyz="0 0 0"/>
    </collision>
  </link>
  <link name="link1">
    <visual>
      <geometry>
        <mesh filename="package://denso_common/meshes/vp6242/visual/link1.dae" scale="0.001 0.001 0.001"/>
      </geometry>
      <origin rpy="-1.570796 3.141592 0" xyz="0 0 0"/>
    </visual>
    <collision>
      <geometry>
        <mesh filename="package://denso_common/meshes/vp6242/collision/link1.dae" scale="0.001 0.001 0.001"/>
      </geometry>
      <origin rpy="-1.570796 3.141592 0" xyz="0 0 0"/>
    </collision>
  </link>
  <joint name="joint1" type="revolute">
    <origin rpy="0 0 0" xyz="0.0 0.0 0.155"/>
    <parent link="base_link"/>
    <child link="link1"/>
    <axis xyz="0 0 1"/>
    <limit effort="0" lower="-2.79252680319" upper="2.79252680319" velocity="1.0"/>
    <calibration falling="0" rising="0"/>
    <dynamics damping="0" friction="0"/>
  </joint>
</robot>

