<?xml version="1.0" ?>
<!-- =================================================================================== -->
<!-- |    This document was autogenerated by xacro from vp6242_dual.xacro              | -->
<!-- |    EDITING THIS FILE BY HAND IS NOT RECOMMENDED                                 | -->
<!-- =================================================================================== -->
<robot name="vp6242_dual" xmlns:xacro="http://www.ros.org/wiki/xacro">
  <link name="base"/>
  <link name="arm0_base"/>
  <link name="arm0_base_link">
    <inertial>
      <mass value="10"/>
      <inertia ixx="1.0" ixy="0.0" ixz="0.0" iyy="1.0" iyz="0.0" izz="1.0"/>
    </inertial>
    <visual>
      <geometry>
        <mesh filename="package://denso_common/meshes/vp6242/visual/base.dae" scale="0.001 0.001 0.001"/>
      </geometry>
      <origin rpy="-1.570796 3.141592 0" xyz="0 0 0"/>
    </visual>
    <collision>
      <geometry>
        <mesh filename="package://denso_common/meshes/vp6242/collision/base.dae" scale="0.001 0.001 0.001"/>
      </geometry>
      <origin rpy="-1.570796 3.141592 0" xyz="0 0 0"/>
    </collision>
  </link>
  <link name="arm0_link1">
    <inertial>
      <mass value="1"/>
      <inertia ixx="1.0" ixy="0.0" ixz="0.0" iyy="1.0" iyz="0.0" izz="1.0"/>
    </inertial>
    <visual>
      <geometry>
        <mesh filename="package://denso_common/meshes/vp6242/visual/link1.dae" scale="0.001 0.001 0.001"/>
      </geometry>
      <origin rpy="-1.570796 3.141592 0" xyz="0 0 0"/>
    </visual>
    <collision>
      <geometry>
        <mesh filename="package://denso_common/meshes/vp6242/collision/link1.dae" scale="0.001 0.001 0.001"/>
      </geometry>
      <origin rpy="-1.570796 3.141592 0" xyz="0 0 0"/>
    </collision>
  </link>
  <link name="arm0_link2">
    <inertial>
      <mass value="1"/>
      <inertia ixx="1.0" ixy="0.0" ixz="0.0" iyy="1.0" iyz="0.0" izz="1.0"/>
    </inertial>
    <visual>
      <geometry>
        <mesh filename="package://denso_common/meshes/vp6242/visual/link2.dae" scale="0.001 0.001 0.001"/>
      </geometry>
      <origin rpy="-1.570796 3.141592 0" xyz="0 0 0"/>
    </visual>
    <collision>
      <geometry>
        <mesh filename="package://denso_common/meshes/vp6242/collision/link2.dae" scale="0.001 0.001 0.001"/>
      </geometry>
      <origin rpy="-1.570796 3.141592 0" xyz="0 0 0"/>
    </collision>
  </link>
  <link name="arm0_link3">
    <inertial>
      <mass value="1"/>
      <inertia ixx="1.0" ixy="0.0" ixz="0.0" iyy="1.0" iyz="0.0" izz="1.0"/>
    </inertial>
    <visual>
      <geometry>
        <mesh filename="package://denso_common/meshes/vp6242/visual/link3.dae" scale="0.001 0.001 0.001"/>
      </geometry>
      <origin rpy="-1.570796 1.570796 0" xyz="0 0 0"/>
    </visual>
    <collision>
      <geometry>
        <mesh filename="package://denso_common/meshes/vp6242/collision/link3.dae" scale="0.001 0.001 0.001"/>
      </geometry>
      <origin rpy="-1.570796 1.570796 0" xyz="0 0 0"/>
    </collision>
  </link>
  <link name="arm0_link4">
    <inertial>
      <mass value="1"/>
      <inertia ixx="1.0" ixy="0.0" ixz="0.0" iyy="1.0" iyz="0.0" izz="1.0"/>
    </inertial>
    <visual>
      <geometry>
        <mesh filename="package://denso_common/meshes/vp6242/visual/link4.dae" scale="0.001 0.001 0.001"/>
      </geometry>
      <origin rpy="0 1.570796 1.570796" xyz="0 0 0.085"/>
    </visual>
    <collision>
      <geometry>
        <mesh filename="package://denso_common/meshes/vp6242/collision/link4.dae" scale="0.001 0.001 0.001"/>
      </geometry>
      <origin rpy="0 1.570796 1.570796" xyz="0 0 0.085"/>
    </collision>
  </link>
  <link name="arm0_link5">
    <inertial>
      <mass value="1"/>
      <inertia ixx="1.0" ixy="0.0" ixz="0.0" iyy="1.0" iyz="0.0" izz="1.0"/>
    </inertial>
    <visual>
      <geometry>
        <mesh filename="package://denso_common/meshes/vp6242/visual/link5.dae" scale="0.001 0.001 0.001"/>
      </geometry>
      <origin rpy="0 1.570796 1.570796" xyz="0 0 0.0"/>
    </visual>
    <collision>
      <geometry>
        <mesh filename="package://denso_common/meshes/vp6242/collision/link5.dae" scale="0.001 0.001 0.001"/>
      </geometry>
      <origin rpy="0 1.570796 1.570796" xyz="0 0 0.0"/>
    </collision>
  </link>
  <link name="arm0_link6">
    <visual>
      <geometry>
        <cylinder length="0.01" radius="0.0205"/>
      </geometry>
      <origin rpy="0 -1.570796 0" xyz="0.0 0.0 0.0"/>
      <material name="plate">
        <color rgba="0.1 0.1 0.1 0.8"/>
      </material>
    </visual>
  </link>
  <link name="arm0_tool0"/>
  <joint name="arm0_base-base_link" type="fixed">
    <parent link="arm0_base"/>
    <child link="arm0_base_link"/>
    <origin rpy="0 0 0" xyz="0 0 0"/>
  </joint>
  <joint name="arm0_joint1" type="revolute">
    <origin rpy="0 0 0" xyz="0.0 0.0 0.155"/>
    <parent link="arm0_base_link"/>
    <child link="arm0_link1"/>
    <axis xyz="0 0 1"/>
    <limit effort="0" lower="-2.792526803" upper="2.792526803" velocity="1.0"/>
    <calibration falling="0" rising="0"/>
    <dynamics damping="0" friction="0"/>
  </joint>
  <joint name="arm0_joint2" type="revolute">
    <origin rpy="0 0 0" xyz="0.0 0.0 0.125"/>
    <parent link="arm0_link1"/>
    <child link="arm0_link2"/>
    <axis xyz="0 1 0"/>
    <limit effort="0" lower="-2.094395102" upper="2.094395102" velocity="1.0"/>
    <calibration falling="0" rising="0"/>
    <dynamics damping="0" friction="0"/>
  </joint>
  <joint name="arm0_joint3" type="revolute">
    <origin rpy="0 0 0" xyz="0.0 0.0 0.210"/>
    <parent link="arm0_link2"/>
    <child link="arm0_link3"/>
    <axis xyz="0 1 0"/>
    <limit effort="0" lower="0.331612558" upper="2.792526803" velocity="1.0"/>
  </joint>
  <joint name="arm0_joint4" type="revolute">
    <origin rpy="0 0 0" xyz="-0.075 0.0 0.0"/>
    <parent link="arm0_link3"/>
    <child link="arm0_link4"/>
    <axis xyz="0 0 1"/>
    <limit effort="0" lower="-2.792526803" upper="2.792526803" velocity="1.0"/>
  </joint>
  <joint name="arm0_joint5" type="revolute">
    <origin rpy="0 0 0" xyz="0.0 0.0 0.210"/>
    <parent link="arm0_link4"/>
    <child link="arm0_link5"/>
    <axis xyz="0 1 0"/>
    <limit effort="0" lower="-2.094395102" upper="2.094395102" velocity="1.0"/>
  </joint>
  <joint name="arm0_joint6" type="revolute">
    <origin rpy="0 -1.570796 0" xyz="0.0 0.0 0.07"/>
    <parent link="arm0_link5"/>
    <child link="arm0_link6"/>
    <axis xyz="1 0 0"/>
    <limit effort="0" lower="-6.283185307" upper="6.283185307" velocity="1.0"/>
  </joint>
  <joint name="arm0_joint6-tool0" type="fixed">
    <parent link="arm0_link6"/>
    <child link="arm0_tool0"/>
    <origin rpy="0 0 0" xyz="0 0 0"/>
  </joint>
  <link name="arm1_base"/>
  <link name="arm1_base_link">
    <inertial>
      <mass value="10"/>
      <inertia ixx="1.0" ixy="0.0" ixz="0.0" iyy="1.0" iyz="0.0" izz="1.0"/>
    </inertial>
    <visual>
      <geometry>
        <mesh filename="package://denso_common/meshes/vp6242/visual/base.dae" scale="0.001 0.001 0.001"/>
      </geometry>
      <origin rpy="-1.570796 3.141592 0" xyz="0 0 0"/>
    </visual>
    <collision>
      <geometry>
        <mesh filename="package://denso_common/meshes/vp6242/collision/base.dae" scale="0.001 0.001 0.001"/>
      </geometry>
      <origin rpy="-1.570796 3.141592 0" xyz="0 0 0"/>
    </collision>
  </link>
  <link name="arm1_link1">
    <inertial>
      <mass value="1"/>
      <inertia ixx="1.0" ixy="0.0" ixz="0.0" iyy="1.0" iyz="0.0" izz="1.0"/>
    </inertial>
    <visual>
      <geometry>
        <mesh filename="package://denso_common/meshes/vp6242/visual/link1.dae" scale="0.001 0.001 0.001"/>
      </geometry>
      <origin rpy="-1.570796 3.141592 0" xyz="0 0 0"/>
    </visual>
    <collision>
      <geometry>
        <mesh filename="package://denso_common/meshes/vp6242/collision/link1.dae" scale="0.001 0.001 0.001"/>
      </geometry>
      <origin rpy="-1.570796 3.141592 0" xyz="0 0 0"/>
    </collision>
  </link>
  <link name="arm1_link2">
    <inertial>
      <mass value="1"/>
      <inertia ixx="1.0" ixy="0.0" ixz="0.0" iyy="1.0" iyz="0.0" izz="1.0"/>
    </inertial>
    <visual>
      <geometry>
        <mesh filename="package://denso_common/meshes/vp6242/visual/link2.dae" scale="0.001 0.001 0.001"/>
      </geometry>
      <origin rpy="-1.570796 3.141592 0" xyz="0 0 0"/>
    </visual>
    <collision>
      <geometry>
        <mesh filename="package://denso_common/meshes/vp6242/collision/link2.dae" scale="0.001 0.001 0.001"/>
      </geometry>
      <origin rpy="-1.570796 3.141592 0" xyz="0 0 0"/>
    </collision>
  </link>
  <link name="arm1_link3">
    <inertial>
      <mass value="1"/>
      <inertia ixx="1.0" ixy="0.0" ixz="0.0" iyy="1.0" iyz="0.0" izz="1.0"/>
    </inertial>
    <visual>
      <geometry>
        <mesh filename="package://denso_common/meshes/vp6242/visual/link3.dae" scale="0.001 0.001 0.001"/>
      </geometry>
      <origin rpy="-1.570796 1.570796 0" xyz="0 0 0"/>
    </visual>
    <collision>
      <geometry>
        <mesh filename="package://denso_common/meshes/vp6242/collision/link3.dae" scale="0.001 0.001 0.001"/>
      </geometry>
      <origin rpy="-1.570796 1.570796 0" xyz="0 0 0"/>
    </collision>
  </link>
  <link name="arm1_link4">
    <inertial>
      <mass value="1"/>
      <inertia ixx="1.0" ixy="0.0" ixz="0.0" iyy="1.0" iyz="0.0" izz="1.0"/>
    </inertial>
    <visual>
      <geometry>
        <mesh filename="package://denso_common/meshes/vp6242/visual/link4.dae" scale="0.001 0.001 0.001"/>
      </geometry>
      <origin rpy="0 1.570796 1.570796" xyz="0 0 0.085"/>
    </visual>
    <collision>
      <geometry>
        <mesh filename="package://denso_common/meshes/vp6242/collision/link4.dae" scale="0.001 0.001 0.001"/>
      </geometry>
      <origin rpy="0 1.570796 1.570796" xyz="0 0 0.085"/>
    </collision>
  </link>
  <link name="arm1_link5">
    <inertial>
      <mass value="1"/>
      <inertia ixx="1.0" ixy="0.0" ixz="0.0" iyy="1.0" iyz="0.0" izz="1.0"/>
    </inertial>
    <visual>
      <geometry>
        <mesh filename="package://denso_common/meshes/vp6242/visual/link5.dae" scale="0.001 0.001 0.001"/>
      </geometry>
      <origin rpy="0 1.570796 1.570796" xyz="0 0 0.0"/>
    </visual>
    <collision>
      <geometry>
        <mesh filename="package://denso_common/meshes/vp6242/collision/link5.dae" scale="0.001 0.001 0.001"/>
      </geometry>
      <origin rpy="0 1.570796 1.570796" xyz="0 0 0.0"/>
    </collision>
  </link>
  <link name="arm1_link6">
    <visual>
      <geometry>
        <cylinder length="0.01" radius="0.0205"/>
      </geometry>
      <origin rpy="0 -1.570796 0" xyz="0.0 0.0 0.0"/>
      <material name="plate">
        <color rgba="0.1 0.1 0.1 0.8"/>
      </material>
    </visual>
  </link>
  <link name="arm1_tool0"/>
  <joint name="arm1_base-base_link" type="fixed">
    <parent link="arm1_base"/>
    <child link="arm1_base_link"/>
    <origin rpy="0 0 0" xyz="0 0 0"/>
  </joint>
  <joint name="arm1_joint1" type="revolute">
    <origin rpy="0 0 0" xyz="0.0 0.0 0.155"/>
    <parent link="arm1_base_link"/>
    <child link="arm1_link1"/>
    <axis xyz="0 0 1"/>
    <limit effort="0" lower="-2.792526803" upper="2.792526803" velocity="1.0"/>
    <calibration falling="0" rising="0"/>
    <dynamics damping="0" friction="0"/>
  </joint>
  <joint name="arm1_joint2" type="revolute">
    <origin rpy="0 0 0" xyz="0.0 0.0 0.125"/>
    <parent link="arm1_link1"/>
    <child link="arm1_link2"/>
    <axis xyz="0 1 0"/>
    <limit effort="0" lower="-2.094395102" upper="2.094395102" velocity="1.0"/>
    <calibration falling="0" rising="0"/>
    <dynamics damping="0" friction="0"/>
  </joint>
  <joint name="arm1_joint3" type="revolute">
    <origin rpy="0 0 0" xyz="0.0 0.0 0.210"/>
    <parent link="arm1_link2"/>
    <child link="arm1_link3"/>
    <axis xyz="0 1 0"/>
    <limit effort="0" lower="0.331612558" upper="2.792526803" velocity="1.0"/>
  </joint>
  <joint name="arm1_joint4" type="revolute">
    <origin rpy="0 0 0" xyz="-0.075 0.0 0.0"/>
    <parent link="arm1_link3"/>
    <child link="arm1_link4"/>
    <axis xyz="0 0 1"/>
    <limit effort="0" lower="-2.792526803" upper="2.792526803" velocity="1.0"/>
  </joint>
  <joint name="arm1_joint5" type="revolute">
    <origin rpy="0 0 0" xyz="0.0 0.0 0.210"/>
    <parent link="arm1_link4"/>
    <child link="arm1_link5"/>
    <axis xyz="0 1 0"/>
    <limit effort="0" lower="-2.094395102" upper="2.094395102" velocity="1.0"/>
  </joint>
  <joint name="arm1_joint6" type="revolute">
    <origin rpy="0 -1.570796 0" xyz="0.0 0.0 0.07"/>
    <parent link="arm1_link5"/>
    <child link="arm1_link6"/>
    <axis xyz="1 0 0"/>
    <limit effort="0" lower="-6.283185307" upper="6.283185307" velocity="1.0"/>
  </joint>
  <joint name="arm1_joint6-tool0" type="fixed">
    <parent link="arm1_link6"/>
    <child link="arm1_tool0"/>
    <origin rpy="0 0 0" xyz="0 0 0"/>
  </joint>
  <joint name="base_arm0" type="fixed">
    <parent link="base"/>
    <child link="arm0_base"/>
    <origin rpy="0 0 0" xyz="0 -0.5 0"/>
  </joint>
  <joint name="base_arm1" type="fixed">
    <parent link="base"/>
    <child link="arm1_base"/>
    <origin rpy="0 0 0" xyz="0 0.5 0"/>
  </joint>
</robot>

